<?xml version="1.0"?>
<!-- created with Phobos 1.0.1 "Capricious Choutengan" -->
  <robot name="rover">

    <link name="Wheel_Front_Left">
      <inertial>
        <origin xyz="0 0 0" rpy="0 0 0"/>
        <mass value="0.96"/>
        <inertia ixx="2e-05" ixy="0" ixz="0" iyy="2e-05" iyz="0" izz="2e-05"/>
      </inertial>
      <visual name="Wheel_Front_Left">
        <origin xyz="0 0 0" rpy="-1.5708 0 0"/>
        <geometry>
          <mesh filename="package://rda_ros/example/auto_driving/car_model/meshes/dae/wheel_FL.dae" scale="0.01 0.01 0.01"/>
        </geometry>
        <material name="MI_CarExterior_TeslaM3"/>
      </visual>
      <collision name="Wheel_Front_Left">
        <origin xyz="0.00386 8e-05 0.04227" rpy="-1.5708 0 0"/>
        <geometry>
          <cylinder radius="0.37507" length="0.75014"/>
        </geometry>
      </collision>
    </link>

    <link name="Wheel_Front_Right">
      <inertial>
        <origin xyz="0 0 0" rpy="0 0 0"/>
        <mass value="0.96"/>
        <inertia ixx="2e-05" ixy="0" ixz="0" iyy="2e-05" iyz="0" izz="2e-05"/>
      </inertial>
      <visual name="Wheel_Front_Right">
        <origin xyz="0 0 0" rpy="-1.5708 0 0"/>
        <geometry>
          <mesh filename="package://rda_ros/example/auto_driving/car_model/meshes/dae/wheel_FR.dae" scale="0.01 0.01 0.01"/>
        </geometry>
        <material name="MI_CarExterior_TeslaM3"/>
      </visual>
      <collision name="Wheel_Front_Right">
        <origin xyz="-0.00386 -0.00015 -0.04227" rpy="-1.5708 0 0"/>
        <geometry>
          <cylinder radius="0.37442" length="0.74883"/>
        </geometry>
      </collision>
    </link>

    <link name="Wheel_Rear_Left">
      <inertial>
        <origin xyz="0 0 0" rpy="0 0 0"/>
        <mass value="0.96"/>
        <inertia ixx="2e-05" ixy="0" ixz="0" iyy="2e-05" iyz="0" izz="2e-05"/>
      </inertial>
      <visual name="Wheel_Rear_Left">
        <origin xyz="0 0 0" rpy="-1.5708 0 0"/>
        <geometry>
          <mesh filename="package://rda_ros/example/auto_driving/car_model/meshes/dae/wheel_RL.dae" scale="0.01 0.01 0.01"/>
        </geometry>
        <material name="MI_CarExterior_TeslaM3"/>
      </visual>
      <collision name="Wheel_Rear_Left">
        <origin xyz="0.00387 8e-05 0.04227" rpy="-1.5708 0 0"/>
        <geometry>
          <cylinder radius="0.37507" length="0.75014"/>
        </geometry>
      </collision>
    </link>

    <link name="Wheel_Rear_Right">
      <inertial>
        <origin xyz="0 0 0" rpy="0 0 0"/>
        <mass value="0.96"/>
        <inertia ixx="2e-05" ixy="0" ixz="0" iyy="2e-05" iyz="0" izz="2e-05"/>
      </inertial>
      <visual name="Wheel_Rear_Right">
        <origin xyz="0 0 0" rpy="-1.5708 0 0"/>
        <geometry>
          <mesh filename="package://rda_ros/example/auto_driving/car_model/meshes/dae/wheel_RR.dae" scale="0.01 0.01 0.01"/>
        </geometry>
        <material name="MI_CarExterior_TeslaM3"/>
      </visual>
      <collision name="Wheel_Rear_Right">
        <origin xyz="-0.00386 8e-05 -0.04227" rpy="-1.5708 0 0"/>
        <geometry>
          <cylinder radius="0.37507" length="0.75014"/>
        </geometry>
      </collision>
    </link>

    <link name="agent_0">
      <inertial>
        <origin xyz="0 0 0" rpy="0 0 0"/>
        <mass value="0.96"/>
        <inertia ixx="2e-05" ixy="0" ixz="0" iyy="2e-05" iyz="0" izz="2e-05"/>
      </inertial>
      <visual name="Body">
        <origin xyz="0 0 0" rpy="0 0 0"/>
        <geometry>
          <mesh filename="package://rda_ros/example/auto_driving/car_model/meshes/dae/body.dae" scale="0.01 0.01 0.01"/>
        </geometry>
        <material name="MI_CarGlass_TeslaM3"/>
      </visual>
    </link>

    <joint name="Wheel_Front_Left.000" type="revolute">
      <origin xyz="1.60131 0.85652 -0.40969" rpy="1.5708 0 0"/>
      <parent link="agent_0"/>
      <child link="Wheel_Front_Left"/>
      <axis xyz="0 0 1.0"/>
      <limit lower="-3.14" upper="3.14" effort="2.4" velocity="1.02"/>
    </joint>

    <joint name="Wheel_Front_Right.000" type="revolute">
      <origin xyz="1.60904 -0.89265 -0.40946" rpy="1.5708 0 0"/>
      <parent link="agent_0"/>
      <child link="Wheel_Front_Right"/>
      <axis xyz="0 0 1.0"/>
      <limit lower="-3.14" upper="3.14" effort="2.4" velocity="1.02"/>
    </joint>

    <joint name="Wheel_Rear_Left.000" type="revolute">
      <origin xyz="-1.39969 0.85652 -0.40969" rpy="1.5708 0 0"/>
      <parent link="agent_0"/>
      <child link="Wheel_Rear_Left"/>
      <axis xyz="0 0 1.0"/>
      <limit lower="-3.14" upper="3.14" effort="2.4" velocity="1.02"/>
    </joint>

    <joint name="Wheel_Rear_Right.000" type="revolute">
      <origin xyz="-1.39196 -0.89265 -0.40969" rpy="1.5708 0 0"/>
      <parent link="agent_0"/>
      <child link="Wheel_Rear_Right"/>
      <axis xyz="0 0 1.0"/>
      <limit lower="-3.14" upper="3.14" effort="2.4" velocity="1.02"/>
    </joint>

    <material name="MI_CarExterior_TeslaM3">
      <color rgba="0 0 0 1.0"/>
    </material>

    <material name="MI_CarGlass_TeslaM3">
      <color rgba="0.8 0.8 0.8 1.0"/>
    </material>

  </robot>
